Traceback (most recent call last):
  File "/usr/lib/python3.7/site-packages/urllib3/connectionpool.py", line 384, in _make_request
    six.raise_from(e, None)
  File "<string>", line 2, in raise_from
  File "/usr/lib/python3.7/site-packages/urllib3/connectionpool.py", line 380, in _make_request
    httplib_response = conn.getresponse()
  File "/usr/lib/python3.7/http/client.py", line 1344, in getresponse
    response.begin()
  File "/usr/lib/python3.7/http/client.py", line 306, in begin
    version, status, reason = self._read_status()
  File "/usr/lib/python3.7/http/client.py", line 267, in _read_status
    line = str(self.fp.readline(_MAXLINE + 1), "iso-8859-1")
  File "/usr/lib/python3.7/socket.py", line 589, in readinto
    return self._sock.recv_into(b)
  File "/usr/lib/python3.7/site-packages/urllib3/contrib/pyopenssl.py", line 310, in recv_into
    raise timeout('The read operation timed out')
socket.timeout: The read operation timed out
During handling of the above exception, another exception occurred:
Traceback (most recent call last):
  File "/usr/lib/python3.7/site-packages/requests/adapters.py", line 449, in send
    timeout=timeout
  File "/usr/lib/python3.7/site-packages/urllib3/connectionpool.py", line 638, in urlopen
    _stacktrace=sys.exc_info()[2])
  File "/usr/lib/python3.7/site-packages/urllib3/util/retry.py", line 368, in increment
    raise six.reraise(type(error), error, _stacktrace)
  File "/usr/lib/python3.7/site-packages/urllib3/packages/six.py", line 686, in reraise
    raise value
  File "/usr/lib/python3.7/site-packages/urllib3/connectionpool.py", line 600, in urlopen
    chunked=chunked)
  File "/usr/lib/python3.7/site-packages/urllib3/connectionpool.py", line 386, in _make_request
    self._raise_timeout(err=e, url=url, timeout_value=read_timeout)
  File "/usr/lib/python3.7/site-packages/urllib3/connectionpool.py", line 306, in _raise_timeout
    raise ReadTimeoutError(self, url, "Read timed out. (read timeout=%s)" % timeout_value)
urllib3.exceptions.ReadTimeoutError: HTTPSConnectionPool(host='lp.vk.com', port=443): Read timed out. (read timeout=35)
During handling of the above exception, another exception occurred:
Traceback (most recent call last):
  File "/home/BunnyNoBugs/emotions-bot/emotions_bot.py", line 62, in <module>
    for event in long_poll.listen():
  File "/home/BunnyNoBugs/.local/lib/python3.7/site-packages/vk_api/bot_longpoll.py", line 285, in listen
    for event in self.check():
  File "/home/BunnyNoBugs/.local/lib/python3.7/site-packages/vk_api/bot_longpoll.py", line 257, in check
    timeout=self.wait + 10
  File "/usr/lib/python3.7/site-packages/requests/sessions.py", line 546, in get
    return self.request('GET', url, **kwargs)
  File "/usr/lib/python3.7/site-packages/requests/sessions.py", line 533, in request
    resp = self.send(prep, **send_kwargs)
  File "/usr/lib/python3.7/site-packages/requests/sessions.py", line 646, in send
    r = adapter.send(request, **kwargs)
  File "/usr/lib/python3.7/site-packages/requests/adapters.py", line 529, in send
    raise ReadTimeout(e, request=request)
requests.exceptions.ReadTimeout: HTTPSConnectionPool(host='lp.vk.com', port=443): Read timed out. (read timeout=35)